<?xml version="1.0" encoding="utf-8"?>
<!-- =================================================================================== -->
<!-- |    This document was autogenerated by xacro from arm.xacro                      | -->
<!-- |    EDITING THIS FILE BY HAND IS NOT RECOMMENDED                                 | -->
<!-- =================================================================================== -->
<robot name="arm">
  <!-- Defining the colors used in this robot -->
  <material name="Black">
    <color rgba="0 0 0 1"/>
  </material>
  <material name="White">
    <color rgba="1 1 1 1"/>
  </material>
  <material name="Blue">
    <color rgba="0 0 1 1"/>
  </material>
  <material name="Red">
    <color rgba="1 0 0 1"/>
  </material>
  <!-- ///////////////////////////////////////   BOTTOM JOINT   ////////////////////////////////////////// -->
  <joint name="bottom_joint" type="fixed">
    <origin rpy="0 0 0" xyz="0 0 0"/>
    <parent link="base_link"/>
    <child link="bottom_link"/>
  </joint>
  <!-- ///////////////////////////////////////   BOTTOM LINK   ////////////////////////////////////////// -->
  <link name="bottom_link">
    <visual>
      <origin rpy="0 0 0" xyz=" 0 0 -0.02"/>
      <geometry>
        <box size="1 1 0.02"/>
      </geometry>
      <material name="Brown"/>
    </visual>
    <collision>
      <origin rpy="0 0 0" xyz=" 0 0 -0.02"/>
      <geometry>
        <box size="1 1 0.02"/>
      </geometry>
    </collision>
    <inertial>
      <mass value="500"/>
      <inertia ixx="1.0" ixy="0.0" ixz="0.0" iyy="0.5" iyz="0.0" izz="1.0"/>
    </inertial>
  </link>
  <!-- /////////////////////////////////////   BASE LINK    ////////////////////////////////////////////// -->
  <link name="base_link">
    <visual>
      <origin rpy="0 0 0" xyz="0 0 0"/>
      <geometry>
        <mesh filename="package://xarm_description/meshes/base_link.STL"/>
      </geometry>
      <material name="White"/>
    </visual>
    <collision>
      <origin rpy="0 0 0" xyz="0 0 0"/>
      <geometry>
        <mesh filename="package://xarm_description/meshes/base_link.STL"/>
      </geometry>
    </collision>
  </link>
  <!-- ///////////////////////////////////////   JOINT1   ////////////////////////////////////////// -->
  <joint name="joint1" type="revolute">
    <parent link="base_link"/>
    <child link="link1"/>
    <origin rpy="0 0 0" xyz="0 0 0.0335"/>
    <axis xyz="0 0 1"/>
    <limit effort="300" lower="-2.09439333333" upper="2.09439333333" velocity="1"/>
    <dynamics damping="50" friction="1"/>
  </joint>
  <!-- /////////////////////////////////////   LINK1  ////////////////////////////////////////////// -->
  <link name="link1">
    <visual>
      <origin rpy="0 0 0" xyz="0 0 0"/>
      <geometry>
        <mesh filename="package://xarm_description/meshes/link_1.STL"/>
      </geometry>
      <material name="Blue"/>
    </visual>
    <collision>
      <origin rpy="0 0 0" xyz="0 0 0"/>
      <geometry>
        <mesh filename="package://xarm_description/meshes/link_1.STL"/>
      </geometry>
    </collision>
    <inertial>
      <mass value="1"/>
      <inertia ixx="1.0" ixy="0.0" ixz="0.0" iyy="0.5" iyz="0.0" izz="1.0"/>
    </inertial>
  </link>
  <!-- ///////////////////////////////////////   JOINT2   ////////////////////////////////////////// -->
  <joint name="joint2" type="revolute">
    <parent link="link1"/>
    <child link="link2"/>
    <origin rpy="3.14159 1.570795 0" xyz="-0.022 -0.021 0.028"/>
    <axis xyz="0 0 1"/>
    <limit effort="300" lower="-2.09439333333" upper="2.09439333333" velocity="1"/>
    <dynamics damping="50" friction="1"/>
  </joint>
  <!-- ///////////////////////////////////////   LINK2  ////////////////////////////////////////////// -->
  <link name="link2">
    <visual>
      <origin rpy="0 0 0" xyz="0 0 0"/>
      <geometry>
        <mesh filename="package://xarm_description/meshes/link_2.STL"/>
      </geometry>
      <material name="White"/>
    </visual>
    <collision>
      <origin rpy="0 0 0" xyz="0 0 0"/>
      <geometry>
        <mesh filename="package://xarm_description/meshes/link_2.STL"/>
      </geometry>
    </collision>
    <inertial>
      <mass value="1"/>
      <inertia ixx="1.0" ixy="0.0" ixz="0.0" iyy="0.5" iyz="0.0" izz="1.0"/>
    </inertial>
  </link>
  <!-- ///////////////////////////////////////   JOINT3   ////////////////////////////////////////// -->
  <joint name="joint3" type="revolute">
    <parent link="link2"/>
    <child link="link3"/>
    <origin rpy="-3.14159 0 0" xyz="-0.111 0 -0.035"/>
    <axis xyz="0 0 1"/>
    <limit effort="300" lower="-2.09439333333" upper="2.09439333333" velocity="1"/>
    <dynamics damping="50" friction="1"/>
  </joint>
  <!-- /////////////////////////////////   LINK3  ///////////////////////////////////////////////////// -->
  <link name="link3">
    <visual>
      <origin rpy="0 0 0" xyz="0 0 0"/>
      <geometry>
        <mesh filename="package://xarm_description/meshes/link_3.STL"/>
      </geometry>
      <material name="Blue"/>
    </visual>
    <collision>
      <origin rpy="0 0 0" xyz="0 0 0"/>
      <geometry>
        <mesh filename="package://xarm_description/meshes/link_3.STL"/>
      </geometry>
    </collision>
    <inertial>
      <mass value="1"/>
      <inertia ixx="1.0" ixy="0.0" ixz="0.0" iyy="0.5" iyz="0.0" izz="1.0"/>
    </inertial>
  </link>
  <!-- ///////////////////////////////////////   JOINT3   ////////////////////////////////////////// -->
  <joint name="joint4" type="revolute">
    <parent link="link3"/>
    <child link="link4"/>
    <origin rpy="3.14159 0 0" xyz="-0.096 0 -0.034"/>
    <axis xyz="0 0 1"/>
    <limit effort="300" lower="-2.09439333333" upper="2.09439333333" velocity="1"/>
    <dynamics damping="50" friction="1"/>
  </joint>
  <!-- ///////////////////////////////////   LINK4  //////////////////////////////////////////////// -->
  <link name="link4">
    <visual>
      <origin rpy="0 0 0" xyz="0 0 0"/>
      <geometry>
        <mesh filename="package://xarm_description/meshes/link_4.STL"/>
      </geometry>
      <material name="White"/>
    </visual>
    <collision>
      <origin rpy="0 0 0" xyz="0 0 0"/>
      <geometry>
        <mesh filename="package://xarm_description/meshes/link_4.STL"/>
      </geometry>
    </collision>
    <inertial>
      <mass value="1"/>
      <inertia ixx="1.0" ixy="0.0" ixz="0.0" iyy="0.5" iyz="0.0" izz="1.0"/>
    </inertial>
  </link>
  <!-- ///////////////////////////////////////   JOINT4   ////////////////////////////////////////// -->
  <joint name="joint5" type="revolute">
    <parent link="link4"/>
    <child link="link5"/>
    <origin rpy="1.570795 0 -1.570795" xyz="-0.053 0 -0.021"/>
    <axis xyz="0 0 -1"/>
    <limit effort="300" lower="-2.09439333333" upper="2.09439333333" velocity="1"/>
    <dynamics damping="50" friction="1"/>
  </joint>
  <!-- //////////////////////////////////   LINK5  ///////////////////////////////////////////////// -->
  <link name="link5">
    <visual>
      <origin rpy="0 0 0" xyz="0 0 0"/>
      <geometry>
        <mesh filename="package://xarm_description/meshes/gripper.STL"/>
      </geometry>
      <material name="Blue"/>
    </visual>
    <collision>
      <origin rpy="0 0 0" xyz="0 0 0"/>
      <geometry>
        <mesh filename="package://xarm_description/meshes/gripper.STL"/>
      </geometry>
    </collision>
    <inertial>
      <mass value="1"/>
      <inertia ixx="1.0" ixy="0.0" ixz="0.0" iyy="0.5" iyz="0.0" izz="1.0"/>
    </inertial>
  </link>
  <!-- ///////////////////////////////////////   GRIPPER RIGHT JOINT1   ////////////////////////////////////////// -->
  <joint name="gripper_right_joint1" type="revolute">
    <parent link="link5"/>
    <child link="gripper_right_link1"/>
    <origin rpy="1.570795 -0.7853975 -1.570795" xyz="-0.008 -0.014 0.030"/>
    <axis xyz="0 0 -1"/>
    <limit effort="300" lower="-0.628318" upper="0.628318" velocity="1"/>
    <dynamics damping="50" friction="1"/>
  </joint>
  <!-- ///////////////////////////////////////   GRIPPER RIGHT LINK1   ////////////////////////////////////////// -->
  <link name="gripper_right_link1">
    <visual>
      <origin rpy="0 0 0" xyz="0 0 0"/>
      <geometry>
        <mesh filename="package://xarm_description/meshes/gripper_r1.STL"/>
      </geometry>
      <material name="White"/>
    </visual>
    <collision>
      <origin rpy="0 0 0" xyz="0 0 0"/>
      <geometry>
        <mesh filename="package://xarm_description/meshes/gripper_r1.STL"/>
      </geometry>
    </collision>
    <inertial>
      <mass value="1"/>
      <inertia ixx="1.0" ixy="0.0" ixz="0.0" iyy="0.5" iyz="0.0" izz="1.0"/>
    </inertial>
  </link>
  <!-- ///////////////////////////////////////   GRIPPER RIGHT JOINT2   ////////////////////////////////////////// -->
  <joint name="gripper_right_joint2" type="revolute">
    <parent link="gripper_right_link1"/>
    <child link="gripper_right_link2"/>
    <origin rpy="0 0 1.30899583333" xyz="0.029 -0.002 0.0039"/>
    <axis xyz="0 0 1"/>
    <limit effort="300" lower="-0.628318" upper="0.628318" velocity="1"/>
    <dynamics damping="50" friction="1"/>
    <mimic joint="gripper_right_joint1" multiplier="1" offset="0"/>
  </joint>
  <gazebo>
    <plugin filename="libroboticsgroup_gazebo_mimic_joint_plugin.so" name="gripper_right_joint2mimic_joint_plugin">
      <joint>gripper_right_joint1</joint>
      <mimicJoint>gripper_right_joint2</mimicJoint>
      <multiplier>1.0</multiplier>
      <offset>0</offset>
      <sensitiveness>0.0</sensitiveness>
      <!-- if absolute difference between setpoint and process value is below this threshold, do nothing; 0.0 = disable [rad] -->
      <maxEffort>10.0</maxEffort>
      <!-- only taken into account if has_pid:=true [Nm] -->
      <robotNamespace>/arm</robotNamespace>
    </plugin>
  </gazebo>
  <!-- ///////////////////////////////////////   GRIPPER RIGHT LINK2   ////////////////////////////////////////// -->
  <link name="gripper_right_link2">
    <visual>
      <origin rpy="0 0 0" xyz="0 0 0"/>
      <geometry>
        <mesh filename="package://xarm_description/meshes/end_r.STL"/>
      </geometry>
      <material name="White"/>
    </visual>
    <collision>
      <origin rpy="0 0 0" xyz="0 0 0"/>
      <geometry>
        <mesh filename="package://xarm_description/meshes/end_r.STL"/>
      </geometry>
    </collision>
    <inertial>
      <mass value="1"/>
      <inertia ixx="1.0" ixy="0.0" ixz="0.0" iyy="0.5" iyz="0.0" izz="1.0"/>
    </inertial>
  </link>
  <!-- ///////////////////////////////////////   GRIPPER LEFT JOINT1   ////////////////////////////////////////// -->
  <joint name="gripper_left_joint1" type="revolute">
    <parent link="link5"/>
    <child link="gripper_left_link1"/>
    <origin rpy="-1.570795 -0.7853975 1.570795" xyz="-0.008 0.014 0.030"/>
    <axis xyz="0 0 1"/>
    <limit effort="300" lower="-0.628318" upper="0.628318" velocity="1"/>
    <dynamics damping="50" friction="1"/>
    <mimic joint="gripper_right_joint1" multiplier="1" offset="0"/>
  </joint>
  <gazebo>
    <plugin filename="libroboticsgroup_gazebo_mimic_joint_plugin.so" name="gripper_left_joint1mimic_joint_plugin">
      <joint>gripper_right_joint1</joint>
      <mimicJoint>gripper_left_joint1</mimicJoint>
      <multiplier>1.0</multiplier>
      <offset>0</offset>
      <sensitiveness>0.0</sensitiveness>
      <!-- if absolute difference between setpoint and process value is below this threshold, do nothing; 0.0 = disable [rad] -->
      <maxEffort>10.0</maxEffort>
      <!-- only taken into account if has_pid:=true [Nm] -->
      <robotNamespace>/arm</robotNamespace>
    </plugin>
  </gazebo>
  <!-- ///////////////////////////////////////   GRIPPER LEFT LINK1   ////////////////////////////////////////// -->
  <link name="gripper_left_link1">
    <visual>
      <origin rpy="0 0 0" xyz="0 0 0"/>
      <geometry>
        <mesh filename="package://xarm_description/meshes/gripper_l1.STL"/>
      </geometry>
      <material name="White"/>
    </visual>
    <collision>
      <origin rpy="0 0 0" xyz="0 0 0"/>
      <geometry>
        <mesh filename="package://xarm_description/meshes/gripper_l1.STL"/>
      </geometry>
    </collision>
    <inertial>
      <mass value="1"/>
      <inertia ixx="1.0" ixy="0.0" ixz="0.0" iyy="0.5" iyz="0.0" izz="1.0"/>
    </inertial>
  </link>
  <!-- ///////////////////////////////////////   GRIPPER LEFT JOINT2   ////////////////////////////////////////// -->
  <joint name="gripper_left_joint2" type="revolute">
    <parent link="gripper_left_link1"/>
    <child link="gripper_left_link2"/>
    <origin rpy="0 0 -1.30899583333" xyz="0.029 -0.001 0.003"/>
    <axis xyz="0 0 1"/>
    <limit effort="300" lower="-0.628318" upper="0.628318" velocity="1"/>
    <dynamics damping="50" friction="1"/>
    <mimic joint="gripper_right_joint2" multiplier="-1" offset="0"/>
  </joint>
  <gazebo>
    <plugin filename="libroboticsgroup_gazebo_mimic_joint_plugin.so" name="gripper_left_joint2mimic_joint_plugin">
      <joint>gripper_right_joint2</joint>
      <mimicJoint>gripper_left_joint2</mimicJoint>
      <multiplier>-1.0</multiplier>
      <offset>0</offset>
      <sensitiveness>0.0</sensitiveness>
      <!-- if absolute difference between setpoint and process value is below this threshold, do nothing; 0.0 = disable [rad] -->
      <maxEffort>10.0</maxEffort>
      <!-- only taken into account if has_pid:=true [Nm] -->
      <robotNamespace>/arm</robotNamespace>
    </plugin>
  </gazebo>
  <!-- ///////////////////////////////////////   GRIPPER LEFT LINK2   ////////////////////////////////////////// -->
  <link name="gripper_left_link2">
    <visual>
      <origin rpy="0 0 0" xyz="0 0 0"/>
      <geometry>
        <mesh filename="package://xarm_description/meshes/end_l.STL"/>
      </geometry>
      <material name="White"/>
    </visual>
    <collision>
      <origin rpy="0 0 0" xyz="0 0 0"/>
      <geometry>
        <mesh filename="package://xarm_description/meshes/end_l.STL"/>
      </geometry>
    </collision>
    <inertial>
      <mass value="1"/>
      <inertia ixx="1.0" ixy="0.0" ixz="0.0" iyy="0.5" iyz="0.0" izz="1.0"/>
    </inertial>
  </link>
  <!-- ///////////////////////////////////////   GRASPING FRAME   ////////////////////////////////////////// -->
  <link name="grasping_frame"/>
  <joint name="grasping_frame_joint" type="fixed">
    <parent link="link5"/>
    <child link="grasping_frame"/>
    <origin rpy="0 0 0" xyz="0 0 0"/>
  </joint>
  <!-- /////////////////////////////////   Gazebo   ////////////////////////////////////// -->
  <gazebo reference="bottom_link">
    <material>Gazebo/White</material>
  </gazebo>
  <gazebo reference="base_link">
    <material>Gazebo/White</material>
  </gazebo>
  <gazebo reference="link1">
    <material>Gazebo/Blue</material>
  </gazebo>
  <gazebo reference="link2">
    <material>Gazebo/White</material>
  </gazebo>
  <gazebo reference="link3">
    <material>Gazebo/Blue</material>
  </gazebo>
  <gazebo reference="link4">
    <material>Gazebo/White</material>
  </gazebo>
  <gazebo reference="link5">
    <material>Gazebo/Blue</material>
  </gazebo>
  <gazebo reference="gripper_right_link1">
    <material>Gazebo/White</material>
  </gazebo>
  <gazebo reference="gripper_right_link2">
    <material>Gazebo/White</material>
  </gazebo>
  <gazebo reference="gripper_left_link1">
    <material>Gazebo/White</material>
  </gazebo>
  <gazebo reference="gripper_left_link2">
    <material>Gazebo/White</material>
  </gazebo>
  <transmission name="tran1">
    <type>transmission_interface/SimpleTransmission</type>
    <joint name="joint1">
      <hardwareInterface>hardware_interface/PositionJointInterface</hardwareInterface>
    </joint>
    <actuator name="motor1">
      <hardwareInterface>hardware_interface/PositionJointInterface</hardwareInterface>
      <mechanicalReduction>1</mechanicalReduction>
    </actuator>
  </transmission>
  <transmission name="tran1">
    <type>transmission_interface/SimpleTransmission</type>
    <joint name="joint2">
      <hardwareInterface>hardware_interface/PositionJointInterface</hardwareInterface>
    </joint>
    <actuator name="motor1">
      <hardwareInterface>hardware_interface/PositionJointInterface</hardwareInterface>
      <mechanicalReduction>1</mechanicalReduction>
    </actuator>
  </transmission>
  <transmission name="tran1">
    <type>transmission_interface/SimpleTransmission</type>
    <joint name="joint3">
      <hardwareInterface>hardware_interface/PositionJointInterface</hardwareInterface>
    </joint>
    <actuator name="motor1">
      <hardwareInterface>hardware_interface/PositionJointInterface</hardwareInterface>
      <mechanicalReduction>1</mechanicalReduction>
    </actuator>
  </transmission>
  <transmission name="tran1">
    <type>transmission_interface/SimpleTransmission</type>
    <joint name="joint4">
      <hardwareInterface>hardware_interface/PositionJointInterface</hardwareInterface>
    </joint>
    <actuator name="motor1">
      <hardwareInterface>hardware_interface/PositionJointInterface</hardwareInterface>
      <mechanicalReduction>1</mechanicalReduction>
    </actuator>
  </transmission>
  <transmission name="tran1">
    <type>transmission_interface/SimpleTransmission</type>
    <joint name="joint5">
      <hardwareInterface>hardware_interface/PositionJointInterface</hardwareInterface>
    </joint>
    <actuator name="motor1">
      <hardwareInterface>hardware_interface/PositionJointInterface</hardwareInterface>
      <mechanicalReduction>1</mechanicalReduction>
    </actuator>
  </transmission>
  <transmission name="tran1">
    <type>transmission_interface/SimpleTransmission</type>
    <joint name="gripper_right_joint1">
      <hardwareInterface>hardware_interface/PositionJointInterface</hardwareInterface>
    </joint>
    <actuator name="motor1">
      <hardwareInterface>hardware_interface/PositionJointInterface</hardwareInterface>
      <mechanicalReduction>1</mechanicalReduction>
    </actuator>
  </transmission>
  <!-- ros_control plugin -->
  <gazebo>
    <plugin filename="libgazebo_ros_control.so" name="gazebo_ros_control">
      <robotNamespace>/arm</robotNamespace>
    </plugin>
  </gazebo>
</robot>
