<?xml version="1.0"?>
<robot name="arm" xmlns:xacro="http://ros.org/wiki/xacro">

    <!-- Defining the colors used in this robot -->
    <material name="Black">
        <color rgba="0 0 0 1"/>
    </material>

    <material name="White">
        <color rgba="1 1 1 1"/>
    </material>

    <material name="Blue">
        <color rgba="0 0 1 1"/>
    </material>

    <material name="Red">
        <color rgba="1 0 0 1"/>
    </material>

    <!-- Constants -->
    <xacro:property name="M_PI" value="3.14159"/>

    <!-- Inertial matrix -->
    <xacro:macro name="inertial_matrix" params="mass">
        <inertial>
            <mass value="${mass}" />
            <inertia ixx="1.0" ixy="0.0" ixz="0.0" iyy="0.5" iyz="0.0" izz="1.0" />
        </inertial>
    </xacro:macro>

    <xacro:macro name="mimic_joint_plugin_gazebo" params="name_prefix parent_joint mimic_joint has_pid:=false multiplier:=1.0 offset:=0 sensitiveness:=0.0 max_effort:=1.0 robot_namespace:=''">
    <gazebo>
      <plugin name="${name_prefix}mimic_joint_plugin" filename="libroboticsgroup_gazebo_mimic_joint_plugin.so">
        <joint>${parent_joint}</joint>
        <mimicJoint>${mimic_joint}</mimicJoint>
        <xacro:if value="${has_pid}">                     <!-- if set to true, PID parameters from "/gazebo_ros_control/pid_gains/${mimic_joint}" are loaded -->
          <hasPID />
        </xacro:if>
        <multiplier>${multiplier}</multiplier>
        <offset>${offset}</offset>
        <sensitiveness>${sensitiveness}</sensitiveness>   <!-- if absolute difference between setpoint and process value is below this threshold, do nothing; 0.0 = disable [rad] -->
        <maxEffort>${max_effort}</maxEffort>              <!-- only taken into account if has_pid:=true [Nm] -->
        <robotNamespace>/arm</robotNamespace>
      </plugin>
    </gazebo>
  </xacro:macro>

    <!-- ///////////////////////////////////////   BOTTOM JOINT   ////////////////////////////////////////// -->
    <joint name="bottom_joint" type="fixed">
        <origin xyz="0 0 0" rpy="0 0 0" />
        <parent link="base_link"/>
        <child link="bottom_link"/>
    </joint>

    <!-- ///////////////////////////////////////   BOTTOM LINK   ////////////////////////////////////////// -->
    <link name="bottom_link">
        <visual>
              <origin xyz=" 0 0 -0.02"  rpy="0 0 0"/>
                  <geometry>
                       <box size="1 1 0.02" />
                  </geometry>
              <material name="Brown" />
        </visual>
        <collision>
            <origin xyz=" 0 0 -0.02"  rpy="0 0 0"/>
            <geometry>
                <box size="1 1 0.02" />
            </geometry>
        </collision>
        <xacro:inertial_matrix mass="500"/>
    </link>

    <!-- /////////////////////////////////////   BASE LINK    ////////////////////////////////////////////// -->
    <link name="base_link">
        <visual>
            <origin xyz="0 0 0" rpy="0 0 0" />
            <geometry>
                <mesh filename="package://xarm_description/meshes/base_link.STL" />
            </geometry>
            <material name="White" />
        </visual>
        <collision>
            <origin xyz="0 0 0" rpy="0 0 0" />
            <geometry>
                <mesh filename="package://xarm_description/meshes/base_link.STL" />
            </geometry>
        </collision>
    </link>

    <!-- ///////////////////////////////////////   JOINT1   ////////////////////////////////////////// -->
    <joint name="joint1" type="revolute">
        <parent link="base_link"/>
        <child link="link1"/>
        <origin xyz="0 0 0.0335" rpy="0 0 0" />
        <axis xyz="0 0 1" />
        <limit effort="300" velocity="1" lower="-${2*M_PI/3}" upper="${2*M_PI/3}"/>
        <dynamics damping="50" friction="1"/>
    </joint>

    <!-- /////////////////////////////////////   LINK1  ////////////////////////////////////////////// -->
    <link name="link1" >
        <visual>
            <origin xyz="0 0 0" rpy="0 0 0" />
            <geometry>
                <mesh filename="package://xarm_description/meshes/link_1.STL" />
            </geometry>
            <material name="Blue" />
        </visual>
        <collision>
            <origin xyz="0 0 0" rpy="0 0 0" />
            <geometry>
                <mesh filename="package://xarm_description/meshes/link_1.STL" />
            </geometry>
        </collision>
        <xacro:inertial_matrix mass="1"/>
    </link>

    <!-- ///////////////////////////////////////   JOINT2   ////////////////////////////////////////// -->
    <joint name="joint2" type="revolute">
        <parent link="link1"/>
        <child link="link2"/>
        <origin xyz="-0.022 -0.021 0.028" rpy="${M_PI} ${M_PI/2} 0" />
        <axis xyz="0 0 1" />
        <limit effort="300" velocity="1" lower="-${2*M_PI/3}" upper="${2*M_PI/3}"/>
        <dynamics damping="50" friction="1"/>
    </joint>

    <!-- ///////////////////////////////////////   LINK2  ////////////////////////////////////////////// -->
    <link name="link2" >
        <visual>
            <origin xyz="0 0 0" rpy="0 0 0" />
            <geometry>
                <mesh filename="package://xarm_description/meshes/link_2.STL" />
            </geometry>
            <material name="White" />
        </visual>

        <collision>
            <origin xyz="0 0 0" rpy="0 0 0" />
            <geometry>
                <mesh filename="package://xarm_description/meshes/link_2.STL" />
            </geometry>
        </collision>
        <xacro:inertial_matrix mass="1"/>
    </link>

    <!-- ///////////////////////////////////////   JOINT3   ////////////////////////////////////////// -->
    <joint name="joint3" type="revolute">
        <parent link="link2"/>
        <child link="link3"/>
        <origin xyz="-0.111 0 -0.035" rpy="-${M_PI} 0 0" />
        <axis xyz="0 0 1" />
        <limit effort="300" velocity="1" lower="-${2*M_PI/3}" upper="${2*M_PI/3}"/>
        <dynamics damping="50" friction="1"/>
    </joint>

    <!-- /////////////////////////////////   LINK3  ///////////////////////////////////////////////////// -->
    <link name="link3" >
        <visual>
            <origin xyz="0 0 0" rpy="0 0 0" />
            <geometry>
                <mesh filename="package://xarm_description/meshes/link_3.STL" />
            </geometry>
            <material name="Blue" />
        </visual>
        <collision>
            <origin xyz="0 0 0" rpy="0 0 0" />
            <geometry>
                <mesh filename="package://xarm_description/meshes/link_3.STL" />
            </geometry>
        </collision>
        <xacro:inertial_matrix mass="1"/>
    </link>

    <!-- ///////////////////////////////////////   JOINT3   ////////////////////////////////////////// -->
    <joint name="joint4" type="revolute">
        <parent link="link3"/>
        <child link="link4"/>
        <origin xyz="-0.096 0 -0.034" rpy="${M_PI} 0 0" />
        <axis xyz="0 0 1" />
        <limit effort="300" velocity="1" lower="-${2*M_PI/3}" upper="${2*M_PI/3}"/>
        <dynamics damping="50" friction="1"/>
    </joint>

    <!-- ///////////////////////////////////   LINK4  //////////////////////////////////////////////// -->
    <link name="link4" >
        <visual>
            <origin xyz="0 0 0" rpy="0 0 0" />
            <geometry>
                <mesh filename="package://xarm_description/meshes/link_4.STL" />
            </geometry>
            <material name="White" />
        </visual>
        <collision>
            <origin xyz="0 0 0" rpy="0 0 0" />
            <geometry>
                <mesh filename="package://xarm_description/meshes/link_4.STL" />
            </geometry>
        </collision>
        <xacro:inertial_matrix mass="1"/>
    </link>

    <!-- ///////////////////////////////////////   JOINT4   ////////////////////////////////////////// -->
    <joint name="joint5" type="revolute">
        <parent link="link4"/>
        <child link="link5"/>
        <origin xyz="-0.053 0 -0.021" rpy="${M_PI/2} 0 -${M_PI/2}" />
        <axis xyz="0 0 -1" />
        <limit effort="300" velocity="1" lower="-${2*M_PI/3}" upper="${2*M_PI/3}"/>
        <dynamics damping="50" friction="1"/>
    </joint>

    <!-- //////////////////////////////////   LINK5  ///////////////////////////////////////////////// -->
    <link name="link5">
        <visual>
            <origin xyz="0 0 0" rpy="0 0 0" />
            <geometry>
                <mesh filename="package://xarm_description/meshes/gripper.STL" />
            </geometry>
            <material name="Blue" />
        </visual>
        <collision>
            <origin xyz="0 0 0" rpy="0 0 0" />
            <geometry>
                <mesh filename="package://xarm_description/meshes/gripper.STL" />
            </geometry>
        </collision>
        <xacro:inertial_matrix mass="1"/>
    </link>

    <!-- ///////////////////////////////////////   GRIPPER RIGHT JOINT1   ////////////////////////////////////////// -->
    <joint name="gripper_right_joint1" type="revolute">
        <parent link="link5"/>
        <child link="gripper_right_link1"/>
        <origin xyz="-0.008 -0.014 0.030" rpy="${M_PI/2} -${M_PI/4} -${M_PI/2}" />
        <axis xyz="0 0 -1" />
        <limit effort="300" velocity="1" lower="-${M_PI/5}" upper="${M_PI/5}" />
        <dynamics damping="50" friction="1"/>
    </joint>

    <!-- ///////////////////////////////////////   GRIPPER RIGHT LINK1   ////////////////////////////////////////// -->
    <link name="gripper_right_link1">
        <visual>
            <origin xyz="0 0 0" rpy="0 0 0" />
            <geometry>
                <mesh filename="package://xarm_description/meshes/gripper_r1.STL" />
            </geometry>
            <material name="White" />
        </visual>
        <collision>
            <origin xyz="0 0 0" rpy="0 0 0" />
            <geometry>
                <mesh filename="package://xarm_description/meshes/gripper_r1.STL" />
            </geometry>
        </collision>
        <xacro:inertial_matrix mass="1"/>
    </link>

    <!-- ///////////////////////////////////////   GRIPPER RIGHT JOINT2   ////////////////////////////////////////// -->
    <joint name="gripper_right_joint2" type="revolute">
        <parent link="gripper_right_link1"/>
        <child link="gripper_right_link2"/>
        <origin xyz="0.029 -0.002 0.0039" rpy="0 0 ${5*M_PI/12}" />
        <axis xyz="0 0 1" />
        <limit effort="300" velocity="1" lower="-${M_PI/5}" upper="${M_PI/5}" />
        <dynamics damping="50" friction="1"/>
        <mimic joint="gripper_right_joint1" multiplier="1" offset="0" />
    </joint>

    <xacro:mimic_joint_plugin_gazebo name_prefix="gripper_right_joint2"
        parent_joint="gripper_right_joint1" mimic_joint="gripper_right_joint2"
        has_pid="false" multiplier="1.0" max_effort="10.0" />

    <!-- ///////////////////////////////////////   GRIPPER RIGHT LINK2   ////////////////////////////////////////// -->
    <link name="gripper_right_link2">
        <visual>
            <origin xyz="0 0 0" rpy="0 0 0" />
            <geometry>
                <mesh filename="package://xarm_description/meshes/end_r.STL" />
            </geometry>
            <material name="White" />
        </visual>
        <collision>
            <origin xyz="0 0 0" rpy="0 0 0" />
            <geometry>
                <mesh filename="package://xarm_description/meshes/end_r.STL" />
            </geometry>
        </collision>
        <xacro:inertial_matrix mass="1"/>
    </link>

    <!-- ///////////////////////////////////////   GRIPPER LEFT JOINT1   ////////////////////////////////////////// -->
    <joint name="gripper_left_joint1" type="revolute">
        <parent link="link5"/>
        <child link="gripper_left_link1"/>
        <origin xyz="-0.008 0.014 0.030" rpy="-${M_PI/2} -${M_PI/4} ${M_PI/2}" />
        <axis xyz="0 0 1" />
        <limit effort="300" velocity="1" lower="-${M_PI/5}" upper="${M_PI/5}" />
        <dynamics damping="50" friction="1"/>
        <mimic joint="gripper_right_joint1" multiplier="1" offset="0" />
    </joint>

    <xacro:mimic_joint_plugin_gazebo name_prefix="gripper_left_joint1"
        parent_joint="gripper_right_joint1" mimic_joint="gripper_left_joint1"
        has_pid="false" multiplier="1.0" max_effort="10.0" />

    <!-- ///////////////////////////////////////   GRIPPER LEFT LINK1   ////////////////////////////////////////// -->
    <link name="gripper_left_link1">
        <visual>
            <origin xyz="0 0 0" rpy="0 0 0" />
            <geometry>
                <mesh filename="package://xarm_description/meshes/gripper_l1.STL" />
            </geometry>
            <material name="White" />
        </visual>
        <collision>
            <origin xyz="0 0 0" rpy="0 0 0" />
            <geometry>
                <mesh filename="package://xarm_description/meshes/gripper_l1.STL" />
            </geometry>
        </collision>
        <xacro:inertial_matrix mass="1"/>
    </link>

    <!-- ///////////////////////////////////////   GRIPPER LEFT JOINT2   ////////////////////////////////////////// -->
    <joint name="gripper_left_joint2" type="revolute">
        <parent link="gripper_left_link1"/>
        <child link="gripper_left_link2"/>
        <origin xyz="0.029 -0.001 0.003" rpy="0 0 -${5*M_PI/12}" />
        <axis xyz="0 0 1" />
        <limit effort="300" velocity="1" lower="-${M_PI/5}" upper="${M_PI/5}" />
        <dynamics damping="50" friction="1"/>
        <mimic joint="gripper_right_joint2" multiplier="-1" offset="0" />
    </joint>

    <xacro:mimic_joint_plugin_gazebo name_prefix="gripper_left_joint2"
        parent_joint="gripper_right_joint2" mimic_joint="gripper_left_joint2"
        has_pid="false" multiplier="-1.0" max_effort="10.0" />

    <!-- ///////////////////////////////////////   GRIPPER LEFT LINK2   ////////////////////////////////////////// -->
    <link name="gripper_left_link2">
        <visual>
            <origin xyz="0 0 0" rpy="0 0 0" />
            <geometry>
                <mesh filename="package://xarm_description/meshes/end_l.STL" />
            </geometry>
            <material name="White" />
        </visual>
        <collision>
            <origin xyz="0 0 0" rpy="0 0 0" />
            <geometry>
                <mesh filename="package://xarm_description/meshes/end_l.STL" />
            </geometry>
        </collision>
        <xacro:inertial_matrix mass="1"/>
    </link>

    <!-- ///////////////////////////////////////   GRASPING FRAME   ////////////////////////////////////////// -->
    <link name="grasping_frame"/>

    <joint name="grasping_frame_joint" type="fixed">
      <parent link="link5"/>
      <child link="grasping_frame"/>
      <origin xyz="0 0 0" rpy="0 0 0"/>
    </joint>

    <!-- /////////////////////////////////   Gazebo   ////////////////////////////////////// -->
    <gazebo reference="bottom_link">
        <material>Gazebo/White</material>
    </gazebo>
    <gazebo reference="base_link">
        <material>Gazebo/White</material>
    </gazebo>
    <gazebo reference="link1">
        <material>Gazebo/Blue</material>
    </gazebo>
    <gazebo reference="link2">
        <material>Gazebo/White</material>
    </gazebo>
    <gazebo reference="link3">
        <material>Gazebo/Blue</material>
    </gazebo>
    <gazebo reference="link4">
        <material>Gazebo/White</material>
    </gazebo>
    <gazebo reference="link5">
        <material>Gazebo/Blue</material>
    </gazebo>
    <gazebo reference="gripper_right_link1">
        <material>Gazebo/White</material>
    </gazebo>
    <gazebo reference="gripper_right_link2">
        <material>Gazebo/White</material>
    </gazebo>
    <gazebo reference="gripper_left_link1">
        <material>Gazebo/White</material>
    </gazebo>
    <gazebo reference="gripper_left_link2">
        <material>Gazebo/White</material>
    </gazebo>
    
    <!-- Transmissions for ROS Control -->
    <xacro:macro name="transmission_block" params="joint_name">
        <transmission name="tran1">
            <type>transmission_interface/SimpleTransmission</type>
            <joint name="${joint_name}">
                <hardwareInterface>hardware_interface/PositionJointInterface</hardwareInterface>
            </joint>
            <actuator name="motor1">
                <hardwareInterface>hardware_interface/PositionJointInterface</hardwareInterface>
                <mechanicalReduction>1</mechanicalReduction>
            </actuator>
        </transmission>
    </xacro:macro>
    
    <xacro:transmission_block joint_name="joint1"/>
    <xacro:transmission_block joint_name="joint2"/>
    <xacro:transmission_block joint_name="joint3"/>
    <xacro:transmission_block joint_name="joint4"/>
    <xacro:transmission_block joint_name="joint5"/>
    <xacro:transmission_block joint_name="gripper_right_joint1"/>

    <!-- ros_control plugin -->
    <gazebo>
        <plugin name="gazebo_ros_control" filename="libgazebo_ros_control.so">
            <robotNamespace>/arm</robotNamespace>
        </plugin>
    </gazebo>

</robot>
